Workbook

Sheet 진행중
A1: 마감팀 프로젝트 일정 — 담당자만 입력하면 [업무 달력]이 직원별로 실시간 자동 정리됩니다
B3: 기본정보 | I3: 공종 담당 | L3: 마감 세부담당 | U3: 일정 / 상태 | AC3: 회의일정 | AF3: 이슈사항
B4: 순번 | C4: No | D4: 업무명 | E4: 거래처 | F4: 연면적 | G4: 타입수 | H4: 선행작업 | I4: 마감 | J4: 구조 | K4: 토목 | L4: PM | M4: 검토 | N4: 내역 | O4: 가설 | P4: 세대 | Q4: 내부 | R4: 외부 | S4: 창호 | T4: 조적 | U4: 수주일 | V4: 작업시작일 | W4: 납품일 | X4: 소요일수 (자동) | Y4: 우선순위 | Z4: 진행률 (%) | AA4: 현재 상태 | AB4: 비고 | AC4: 인원 | AD4: 일자 | AE4: 내용 | AF4: 마감 | AG4: 구조 | AH4: 토목
B5: =IF(D5="","",ROW()-4) | C5: 2026010 | D5: 구리 수택E구역 주택재개발 2,4BL 견적 | E5: 대형건설 | F5: 95000 | G5: 4 | I5: 송치영 | J5: 신동헌 | K5: X | L5: 송치영 | T5: VIET 조적팀 | V5: 46087 | W5: 46101 | X5: =IF(AND(V5<>"",W5<>""),NETWORKDAYS(V5,W5),"") | Y5: 보통 | Z5: 60 | AA5: 진행중
B6: =IF(D6="","",ROW()-4) | C6: 2026011 | D6: 광양바이오매스 발전소 EPC 설계변경 | E6: 엔지니어링 | F6: 22000 | G6: 1 | I6: 최영배 | J6: X | K6: 오승균 | L6: 최영배 | V6: 46092 | W6: 46101 | X6: =IF(AND(V6<>"",W6<>""),NETWORKDAYS(V6,W6),"") | Y6: 높음 | Z6: 80 | AA6: 진행중 | AB6: 설계변경분
B7: =IF(D7="","",ROW()-4) | C7: 2026012 | D7: 평택고덕 A-64BL 통합형 공공주택 | E7: 종합건설 | F7: 64000 | G7: 3 | H7: 도면접수 | I7: 조한빈 | J7: 박용진 | K7: X | L7: 조한빈 | Q7: 임승주 | S7: VIET 창호팀 | T7: VIET 조적팀 | V7: 46092 | W7: 46115 | X7: =IF(AND(V7<>"",W7<>""),NETWORKDAYS(V7,W7),"") | Y7: 긴급 | Z7: 30 | AA7: 진행중 | AB7: 부대·공용부
B8: =IF(D8="","",ROW()-4) | C8: 2026013 | D8: 남산스퀘어 주거복합 | E8: 시행사 | F8: 48000 | G8: 2 | I8: 이은지 | J8: X | K8: X | L8: 이은지 | P8: 이은지 | R8: 임창열 | S8: 김수겸 | T8: 김수겸 | V8: 46188 | W8: 46206 | X8: =IF(AND(V8<>"",W8<>""),NETWORKDAYS(V8,W8),"") | Y8: 보통 | Z8: 10 | AA8: 시작전 | AB8: 김수겸 창호+조적
B9: =IF(D9="","",ROW()-4) | C9: 2026014 | D9: 마이다스아이티 사옥 | E9: 건설사 | F9: 18000 | G9: 1 | I9: 조한빈 | J9: X | K9: X | L9: 조한빈 | Q9: 임승주 | S9: 김수겸 | V9: 46176 | W9: 46192 | X9: =IF(AND(V9<>"",W9<>""),NETWORKDAYS(V9,W9),"") | Y9: 높음 | Z9: 50 | AA9: 진행중
B10: =IF(D10="","",ROW()-4) | C10: 2026015 | D10: 위례복정역세권 공동주택 | E10: 공공 | F10: 72000 | G10: 3 | I10: 성대용 | J10: 장범선 | K10: X | L10: 성대용 | O10: 원종수 | V10: 46167 | W10: 46185 | X10: =IF(AND(V10<>"",W10<>""),NETWORKDAYS(V10,W10),"") | Y10: 보통 | Z10: 100 | AA10: 완료 | AB10: 검토완료(달력제외)
B11: =IF(D11="","",ROW()-4) | X11: =IF(AND(V11<>"",W11<>""),NETWORKDAYS(V11,W11),"")
B12: =IF(D12="","",ROW()-4) | X12: =IF(AND(V12<>"",W12<>""),NETWORKDAYS(V12,W12),"")
B13: =IF(D13="","",ROW()-4) | X13: =IF(AND(V13<>"",W13<>""),NETWORKDAYS(V13,W13),"")
B14: =IF(D14="","",ROW()-4) | X14: =IF(AND(V14<>"",W14<>""),NETWORKDAYS(V14,W14),"")
B15: =IF(D15="","",ROW()-4) | X15: =IF(AND(V15<>"",W15<>""),NETWORKDAYS(V15,W15),"")
B16: =IF(D16="","",ROW()-4) | X16: =IF(AND(V16<>"",W16<>""),NETWORKDAYS(V16,W16),"")
B17: =IF(D17="","",ROW()-4) | X17: =IF(AND(V17<>"",W17<>""),NETWORKDAYS(V17,W17),"")
B18: =IF(D18="","",ROW()-4) | X18: =IF(AND(V18<>"",W18<>""),NETWORKDAYS(V18,W18),"")
B19: =IF(D19="","",ROW()-4) | X19: =IF(AND(V19<>"",W19<>""),NETWORKDAYS(V19,W19),"")
B20: =IF(D20="","",ROW()-4) | X20: =IF(AND(V20<>"",W20<>""),NETWORKDAYS(V20,W20),"")
B21: =IF(D21="","",ROW()-4) | X21: =IF(AND(V21<>"",W21<>""),NETWORKDAYS(V21,W21),"")
B22: =IF(D22="","",ROW()-4) | X22: =IF(AND(V22<>"",W22<>""),NETWORKDAYS(V22,W22),"")
... B64: =IF(D64="","",ROW()-4) | X64: =IF(AND(V64<>"",W64<>""),NETWORKDAYS(V64,W64),"")

Sheet 📅 업무 달력
A1: 2026년 | H1: 1월 | AM1: 2월 | BO1: 3월 | CT1: 4월 | DX1: 5월 | FC1: 6월 | GG1: 7월 | HL1: 8월 | IQ1: 9월 | JU1: 10월 | KZ1: 11월 | MD1: 12월
A2: 직원 | B2: 업무 (공종) | C2: 시작 | D2: 종료 | H2: 46023 | I2: 46024 | J2: 46025 | K2: 46026 | L2: 46027 | M2: 46028 | N2: 46029 | O2: 46030 | P2: 46031 | Q2: 46032 | R2: 46033 | S2: 46034 | T2: 46035 | U2: 46036 | V2: 46037 | W2: 46038 | X2: 46039 | Y2: 46040 | Z2: 46041 | AA2: 46042 | AB2: 46043 | AC2: 46044 | AD2: 46045 | AE2: 46046 | AF2: 46047 | AG2: 46048 | AH2: 46049 | AI2: 46050 | AJ2: 46051 | AK2: 46052 | AL2: 46053 | AM2: 46054 | AN2: 46055 | AO2: 46056 | AP2: 46057 | AQ2: 46058 | AR2: 46059 | AS2: 46060 | AT2: 46061 | AU2: 46062 | AV2: 46063 | AW2: 46064 | AX2: 46065 | AY2: 46066 | AZ2: 46067 | BA2: 46068 | BB2: 46069 | BC2: 46070 | BD2: 46071 | BE2: 46072 | BF2: 46073 | BG2: 46074 | BH2: 46075 | BI2: 46076 | BJ2: 46077 | BK2: 46078 | BL2: 46079 | BM2: 46080 | BN2: 46081 | BO2: 46082 | BP2: 46083 | BQ2: 46084 | BR2: 46085 | BS2: 46086 | BT2: 46087 | BU2: 46088 | BV2: 46089 | BW2: 46090 | BX2: 46091 | BY2: 46092 | BZ2: 46093 | CA2: 46094 | CB2: 46095 | CC2: 46096 | CD2: 46097 | CE2: 46098 | CF2: 46099 | CG2: 46100 | CH2: 46101 | CI2: 46102 | CJ2: 46103 | CK2: 46104 | CL2: 46105 | CM2: 46106 | CN2: 46107 | CO2: 46108 | CP2: 46109 | CQ2: 46110 | CR2: 46111 | CS2: 46112 | CT2: 46113 | CU2: 46114 | CV2: 46115 | CW2: 46116 | CX2: 46117 | CY2: 46118 | CZ2: 46119 | DA2: 46120 | DB2: 46121 | DC2: 46122 | DD2: 46123 | DE2: 46124 | DF2: 46125 | DG2: 46126 | DH2: 46127 | DI2: 46128 | DJ2: 46129 | DK2: 46130 | DL2: 46131 | DM2: 46132 | DN2: 46133 | DO2: 46134 | DP2: 46135 | DQ2: 46136 | DR2: 46137 | DS2: 46138 | DT2: 46139 | DU2: 46140 | DV2: 46141 | DW2: 46142 | DX2: 46143 | DY2: 46144 | DZ2: 46145 | EA2: 46146 | EB2: 46147 | EC2: 46148 | ED2: 46149 | EE2: 46150 | EF2: 46151 | EG2: 46152 | EH2: 46153 | EI2: 46154 | EJ2: 46155 | EK2: 46156 | EL2: 46157 | EM2: 46158 | EN2: 46159 | EO2: 46160 | EP2: 46161 | EQ2: 46162 | ER2: 46163 | ES2: 46164 | ET2: 46165 | EU2: 46166 | EV2: 46167 | EW2: 46168 | EX2: 46169 | EY2: 46170 | EZ2: 46171 | FA2: 46172 | FB2: 46173 | FC2: 46174 | FD2: 46175 | FE2: 46176 | FF2: 46177 | FG2: 46178 | FH2: 46179 | FI2: 46180 | FJ2: 46181 | FK2: 46182 | FL2: 46183 | FM2: 46184 | FN2: 46185 | FO2: 46186 | FP2: 46187 | FQ2: 46188 | FR2: 46189 | FS2: 46190 | FT2: 46191 | FU2: 46192 | FV2: 46193 | FW2: 46194 | FX2: 46195 | FY2: 46196 | FZ2: 46197 | GA2: 46198 | GB2: 46199 | GC2: 46200 | GD2: 46201 | GE2: 46202 | GF2: 46203 | GG2: 46204 | GH2: 46205 | GI2: 46206 | GJ2: 46207 | GK2: 46208 | GL2: 46209 | GM2: 46210 | GN2: 46211 | GO2: 46212 | GP2: 46213 | GQ2: 46214 | GR2: 46215 | GS2: 46216 | GT2: 46217 | GU2: 46218 | GV2: 46219 | GW2: 46220 | GX2: 46221 | GY2: 46222 | GZ2: 46223 | HA2: 46224 | HB2: 46225 | HC2: 46226 | HD2: 46227 | HE2: 46228 | HF2: 46229 | HG2: 46230 | HH2: 46231 | HI2: 46232 | HJ2: 46233 | HK2: 46234 | HL2: 46235 | HM2: 46236 | HN2: 46237 | HO2: 46238 | HP2: 46239 | HQ2: 46240 | HR2: 46241 | HS2: 46242 | HT2: 46243 | HU2: 46244 | HV2: 46245 | HW2: 46246 | HX2: 46247 | HY2: 46248 | HZ2: 46249 | IA2: 46250 | IB2: 46251 | IC2: 46252 | ID2: 46253 | IE2: 46254 | IF2: 46255 | IG2: 46256 | IH2: 46257 | II2: 46258 | IJ2: 46259 | IK2: 46260 | IL2: 46261 | IM2: 46262 | IN2: 46263 | IO2: 46264 | IP2: 46265 | IQ2: 46266 | IR2: 46267 | IS2: 46268 | IT2: 46269 | IU2: 46270 | IV2: 46271 | IW2: 46272 | IX2: 46273 | IY2: 46274 | IZ2: 46275 | JA2: 46276 | JB2: 46277 | JC2: 46278 | JD2: 46279 | JE2: 46280 | JF2: 46281 | JG2: 46282 | JH2: 46283 | JI2: 46284 | JJ2: 46285 | JK2: 46286 | JL2: 46287 | JM2: 46288 | JN2: 46289 | JO2: 46290 | JP2: 46291 | JQ2: 46292 | JR2: 46293 | JS2: 46294 | JT2: 46295 | JU2: 46296 | JV2: 46297 | JW2: 46298 | JX2: 46299 | JY2: 46300 | JZ2: 46301 | KA2: 46302 | KB2: 46303 | KC2: 46304 | KD2: 46305 | KE2: 46306 | KF2: 46307 | KG2: 46308 | KH2: 46309 | KI2: 46310 | KJ2: 46311 | KK2: 46312 | KL2: 46313 | KM2: 46314 | KN2: 46315 | KO2: 46316 | KP2: 46317 | KQ2: 46318 | KR2: 46319 | KS2: 46320 | KT2: 46321 | KU2: 46322 | KV2: 46323 | KW2: 46324 | KX2: 46325 | KY2: 46326 | KZ2: 46327 | LA2: 46328 | LB2: 46329 | LC2: 46330 | LD2: 46331 | LE2: 46332 | LF2: 46333 | LG2: 46334 | LH2: 46335 | LI2: 46336 | LJ2: 46337 | LK2: 46338 | LL2: 46339 | LM2: 46340 | LN2: 46341 | LO2: 46342 | LP2: 46343 | LQ2: 46344 | LR2: 46345 | LS2: 46346 | LT2: 46347 | LU2: 46348 | LV2: 46349 | LW2: 46350 | LX2: 46351 | LY2: 46352 | LZ2: 46353 | MA2: 46354 | MB2: 46355 | MC2: 46356 | MD2: 46357 | ME2: 46358 | MF2: 46359 | MG2: 46360 | MH2: 46361 | MI2: 46362 | MJ2: 46363 | MK2: 46364 | ML2: 46365 | MM2: 46366 | MN2: 46367 | MO2: 46368 | MP2: 46369 | MQ2: 46370 | MR2: 46371 | MS2: 46372 | MT2: 46373 | MU2: 46374 | MV2: 46375 | MW2: 46376 | MX2: 46377 | MY2: 46378 | MZ2: 46379 | NA2: 46380 | NB2: 46381 | NC2: 46382 | ND2: 46383 | NE2: 46384 | NF2: 46385 | NG2: 46386 | NH2: 46387
A3: [ 국내 마감팀 ]
A4: 최영배 본부장 | B4: =IF($F4="","",INDEX(배정!$B$2:$B$541,$F4)&" ("&INDEX(배정!$C$2:$C$541,$F4)&")") | C4: =IF($F4="","",INDEX(배정!$D$2:$D$541,$F4)) | D4: =IF($F4="","",INDEX(배정!$E$2:$E$541,$F4)) | E4: 최영배 | F4: =IF(ISNA(MATCH($E4&"|"&1,배정!$G$2:$G$541,0)),"",MATCH($E4&"|"&1,배정!$G$2:$G$541,0)) | G4: =IF($F4="","",INDEX(배정!$C$2:$C$541,$F4))
B5: =IF($F5="","",INDEX(배정!$B$2:$B$541,$F5)&" ("&INDEX(배정!$C$2:$C$541,$F5)&")") | C5: =IF($F5="","",INDEX(배정!$D$2:$D$541,$F5)) | D5: =IF($F5="","",INDEX(배정!$E$2:$E$541,$F5)) | E5: 최영배 | F5: =IF(ISNA(MATCH($E5&"|"&2,배정!$G$2:$G$541,0)),"",MATCH($E5&"|"&2,배정!$G$2:$G$541,0)) | G5: =IF($F5="","",INDEX(배정!$C$2:$C$541,$F5))
B6: =IF($F6="","",INDEX(배정!$B$2:$B$541,$F6)&" ("&INDEX(배정!$C$2:$C$541,$F6)&")") | C6: =IF($F6="","",INDEX(배정!$D$2:$D$541,$F6)) | D6: =IF($F6="","",INDEX(배정!$E$2:$E$541,$F6)) | E6: 최영배 | F6: =IF(ISNA(MATCH($E6&"|"&3,배정!$G$2:$G$541,0)),"",MATCH($E6&"|"&3,배정!$G$2:$G$541,0)) | G6: =IF($F6="","",INDEX(배정!$C$2:$C$541,$F6))
B7: =IF($F7="","",INDEX(배정!$B$2:$B$541,$F7)&" ("&INDEX(배정!$C$2:$C$541,$F7)&")") | C7: =IF($F7="","",INDEX(배정!$D$2:$D$541,$F7)) | D7: =IF($F7="","",INDEX(배정!$E$2:$E$541,$F7)) | E7: 최영배 | F7: =IF(ISNA(MATCH($E7&"|"&4,배정!$G$2:$G$541,0)),"",MATCH($E7&"|"&4,배정!$G$2:$G$541,0)) | G7: =IF($F7="","",INDEX(배정!$C$2:$C$541,$F7))
B8: =IF($F8="","",INDEX(배정!$B$2:$B$541,$F8)&" ("&INDEX(배정!$C$2:$C$541,$F8)&")") | C8: =IF($F8="","",INDEX(배정!$D$2:$D$541,$F8)) | D8: =IF($F8="","",INDEX(배정!$E$2:$E$541,$F8)) | E8: 최영배 | F8: =IF(ISNA(MATCH($E8&"|"&5,배정!$G$2:$G$541,0)),"",MATCH($E8&"|"&5,배정!$G$2:$G$541,0)) | G8: =IF($F8="","",INDEX(배정!$C$2:$C$541,$F8))
B9: =IF($F9="","",INDEX(배정!$B$2:$B$541,$F9)&" ("&INDEX(배정!$C$2:$C$541,$F9)&")") | C9: =IF($F9="","",INDEX(배정!$D$2:$D$541,$F9)) | D9: =IF($F9="","",INDEX(배정!$E$2:$E$541,$F9)) | E9: 최영배 | F9: =IF(ISNA(MATCH($E9&"|"&6,배정!$G$2:$G$541,0)),"",MATCH($E9&"|"&6,배정!$G$2:$G$541,0)) | G9: =IF($F9="","",INDEX(배정!$C$2:$C$541,$F9))
B10: =IF($F10="","",INDEX(배정!$B$2:$B$541,$F10)&" ("&INDEX(배정!$C$2:$C$541,$F10)&")") | C10: =IF($F10="","",INDEX(배정!$D$2:$D$541,$F10)) | D10: =IF($F10="","",INDEX(배정!$E$2:$E$541,$F10)) | E10: 최영배 | F10: =IF(ISNA(MATCH($E10&"|"&7,배정!$G$2:$G$541,0)),"",MATCH($E10&"|"&7,배정!$G$2:$G$541,0)) | G10: =IF($F10="","",INDEX(배정!$C$2:$C$541,$F10))
B11: =IF($F11="","",INDEX(배정!$B$2:$B$541,$F11)&" ("&INDEX(배정!$C$2:$C$541,$F11)&")") | C11: =IF($F11="","",INDEX(배정!$D$2:$D$541,$F11)) | D11: =IF($F11="","",INDEX(배정!$E$2:$E$541,$F11)) | E11: 최영배 | F11: =IF(ISNA(MATCH($E11&"|"&8,배정!$G$2:$G$541,0)),"",MATCH($E11&"|"&8,배정!$G$2:$G$541,0)) | G11: =IF($F11="","",INDEX(배정!$C$2:$C$541,$F11))
B12: =IF($F12="","",INDEX(배정!$B$2:$B$541,$F12)&" ("&INDEX(배정!$C$2:$C$541,$F12)&")") | C12: =IF($F12="","",INDEX(배정!$D$2:$D$541,$F12)) | D12: =IF($F12="","",INDEX(배정!$E$2:$E$541,$F12)) | E12: 최영배 | F12: =IF(ISNA(MATCH($E12&"|"&9,배정!$G$2:$G$541,0)),"",MATCH($E12&"|"&9,배정!$G$2:$G$541,0)) | G12: =IF($F12="","",INDEX(배정!$C$2:$C$541,$F12))
B13: =IF($F13="","",INDEX(배정!$B$2:$B$541,$F13)&" ("&INDEX(배정!$C$2:$C$541,$F13)&")") | C13: =IF($F13="","",INDEX(배정!$D$2:$D$541,$F13)) | D13: =IF($F13="","",INDEX(배정!$E$2:$E$541,$F13)) | E13: 최영배 | F13: =IF(ISNA(MATCH($E13&"|"&10,배정!$G$2:$G$541,0)),"",MATCH($E13&"|"&10,배정!$G$2:$G$541,0)) | G13: =IF($F13="","",INDEX(배정!$C$2:$C$541,$F13))
A14: 조한빈 실장 | B14: =IF($F14="","",INDEX(배정!$B$2:$B$541,$F14)&" ("&INDEX(배정!$C$2:$C$541,$F14)&")") | C14: =IF($F14="","",INDEX(배정!$D$2:$D$541,$F14)) | D14: =IF($F14="","",INDEX(배정!$E$2:$E$541,$F14)) | E14: 조한빈 | F14: =IF(ISNA(MATCH($E14&"|"&1,배정!$G$2:$G$541,0)),"",MATCH($E14&"|"&1,배정!$G$2:$G$541,0)) | G14: =IF($F14="","",INDEX(배정!$C$2:$C$541,$F14))
B15: =IF($F15="","",INDEX(배정!$B$2:$B$541,$F15)&" ("&INDEX(배정!$C$2:$C$541,$F15)&")") | C15: =IF($F15="","",INDEX(배정!$D$2:$D$541,$F15)) | D15: =IF($F15="","",INDEX(배정!$E$2:$E$541,$F15)) | E15: 조한빈 | F15: =IF(ISNA(MATCH($E15&"|"&2,배정!$G$2:$G$541,0)),"",MATCH($E15&"|"&2,배정!$G$2:$G$541,0)) | G15: =IF($F15="","",INDEX(배정!$C$2:$C$541,$F15))
B16: =IF($F16="","",INDEX(배정!$B$2:$B$541,$F16)&" ("&INDEX(배정!$C$2:$C$541,$F16)&")") | C16: =IF($F16="","",INDEX(배정!$D$2:$D$541,$F16)) | D16: =IF($F16="","",INDEX(배정!$E$2:$E$541,$F16)) | E16: 조한빈 | F16: =IF(ISNA(MATCH($E16&"|"&3,배정!$G$2:$G$541,0)),"",MATCH($E16&"|"&3,배정!$G$2:$G$541,0)) | G16: =IF($F16="","",INDEX(배정!$C$2:$C$541,$F16))
B17: =IF($F17="","",INDEX(배정!$B$2:$B$541,$F17)&" ("&INDEX(배정!$C$2:$C$541,$F17)&")") | C17: =IF($F17="","",INDEX(배정!$D$2:$D$541,$F17)) | D17: =IF($F17="","",INDEX(배정!$E$2:$E$541,$F17)) | E17: 조한빈 | F17: =IF(ISNA(MATCH($E17&"|"&4,배정!$G$2:$G$541,0)),"",MATCH($E17&"|"&4,배정!$G$2:$G$541,0)) | G17: =IF($F17="","",INDEX(배정!$C$2:$C$541,$F17))
B18: =IF($F18="","",INDEX(배정!$B$2:$B$541,$F18)&" ("&INDEX(배정!$C$2:$C$541,$F18)&")") | C18: =IF($F18="","",INDEX(배정!$D$2:$D$541,$F18)) | D18: =IF($F18="","",INDEX(배정!$E$2:$E$541,$F18)) | E18: 조한빈 | F18: =IF(ISNA(MATCH($E18&"|"&5,배정!$G$2:$G$541,0)),"",MATCH($E18&"|"&5,배정!$G$2:$G$541,0)) | G18: =IF($F18="","",INDEX(배정!$C$2:$C$541,$F18))
B19: =IF($F19="","",INDEX(배정!$B$2:$B$541,$F19)&" ("&INDEX(배정!$C$2:$C$541,$F19)&")") | C19: =IF($F19="","",INDEX(배정!$D$2:$D$541,$F19)) | D19: =IF($F19="","",INDEX(배정!$E$2:$E$541,$F19)) | E19: 조한빈 | F19: =IF(ISNA(MATCH($E19&"|"&6,배정!$G$2:$G$541,0)),"",MATCH($E19&"|"&6,배정!$G$2:$G$541,0)) | G19: =IF($F19="","",INDEX(배정!$C$2:$C$541,$F19))
B20: =IF($F20="","",INDEX(배정!$B$2:$B$541,$F20)&" ("&INDEX(배정!$C$2:$C$541,$F20)&")") | C20: =IF($F20="","",INDEX(배정!$D$2:$D$541,$F20)) | D20: =IF($F20="","",INDEX(배정!$E$2:$E$541,$F20)) | E20: 조한빈 | F20: =IF(ISNA(MATCH($E20&"|"&7,배정!$G$2:$G$541,0)),"",MATCH($E20&"|"&7,배정!$G$2:$G$541,0)) | G20: =IF($F20="","",INDEX(배정!$C$2:$C$541,$F20))
B21: =IF($F21="","",INDEX(배정!$B$2:$B$541,$F21)&" ("&INDEX(배정!$C$2:$C$541,$F21)&")") | C21: =IF($F21="","",INDEX(배정!$D$2:$D$541,$F21)) | D21: =IF($F21="","",INDEX(배정!$E$2:$E$541,$F21)) | E21: 조한빈 | F21: =IF(ISNA(MATCH($E21&"|"&8,배정!$G$2:$G$541,0)),"",MATCH($E21&"|"&8,배정!$G$2:$G$541,0)) | G21: =IF($F21="","",INDEX(배정!$C$2:$C$541,$F21))
B22: =IF($F22="","",INDEX(배정!$B$2:$B$541,$F22)&" ("&INDEX(배정!$C$2:$C$541,$F22)&")") | C22: =IF($F22="","",INDEX(배정!$D$2:$D$541,$F22)) | D22: =IF($F22="","",INDEX(배정!$E$2:$E$541,$F22)) | E22: 조한빈 | F22: =IF(ISNA(MATCH($E22&"|"&9,배정!$G$2:$G$541,0)),"",MATCH($E22&"|"&9,배정!$G$2:$G$541,0)) | G22: =IF($F22="","",INDEX(배정!$C$2:$C$541,$F22))
B23: =IF($F23="","",INDEX(배정!$B$2:$B$541,$F23)&" ("&INDEX(배정!$C$2:$C$541,$F23)&")") | C23: =IF($F23="","",INDEX(배정!$D$2:$D$541,$F23)) | D23: =IF($F23="","",INDEX(배정!$E$2:$E$541,$F23)) | E23: 조한빈 | F23: =IF(ISNA(MATCH($E23&"|"&10,배정!$G$2:$G$541,0)),"",MATCH($E23&"|"&10,배정!$G$2:$G$541,0)) | G23: =IF($F23="","",INDEX(배정!$C$2:$C$541,$F23))
A24: 김재헌 수석 | B24: =IF($F24="","",INDEX(배정!$B$2:$B$541,$F24)&" ("&INDEX(배정!$C$2:$C$541,$F24)&")") | C24: =IF($F24="","",INDEX(배정!$D$2:$D$541,$F24)) | D24: =IF($F24="","",INDEX(배정!$E$2:$E$541,$F24)) | E24: 김재헌 | F24: =IF(ISNA(MATCH($E24&"|"&1,배정!$G$2:$G$541,0)),"",MATCH($E24&"|"&1,배정!$G$2:$G$541,0)) | G24: =IF($F24="","",INDEX(배정!$C$2:$C$541,$F24))
B25: =IF($F25="","",INDEX(배정!$B$2:$B$541,$F25)&" ("&INDEX(배정!$C$2:$C$541,$F25)&")") | C25: =IF($F25="","",INDEX(배정!$D$2:$D$541,$F25)) | D25: =IF($F25="","",INDEX(배정!$E$2:$E$541,$F25)) | E25: 김재헌 | F25: =IF(ISNA(MATCH($E25&"|"&2,배정!$G$2:$G$541,0)),"",MATCH($E25&"|"&2,배정!$G$2:$G$541,0)) | G25: =IF($F25="","",INDEX(배정!$C$2:$C$541,$F25))
B26: =IF($F26="","",INDEX(배정!$B$2:$B$541,$F26)&" ("&INDEX(배정!$C$2:$C$541,$F26)&")") | C26: =IF($F26="","",INDEX(배정!$D$2:$D$541,$F26)) | D26: =IF($F26="","",INDEX(배정!$E$2:$E$541,$F26)) | E26: 김재헌 | F26: =IF(ISNA(MATCH($E26&"|"&3,배정!$G$2:$G$541,0)),"",MATCH($E26&"|"&3,배정!$G$2:$G$541,0)) | G26: =IF($F26="","",INDEX(배정!$C$2:$C$541,$F26))
B27: =IF($F27="","",INDEX(배정!$B$2:$B$541,$F27)&" ("&INDEX(배정!$C$2:$C$541,$F27)&")") | C27: =IF($F27="","",INDEX(배정!$D$2:$D$541,$F27)) | D27: =IF($F27="","",INDEX(배정!$E$2:$E$541,$F27)) | E27: 김재헌 | F27: =IF(ISNA(MATCH($E27&"|"&4,배정!$G$2:$G$541,0)),"",MATCH($E27&"|"&4,배정!$G$2:$G$541,0)) | G27: =IF($F27="","",INDEX(배정!$C$2:$C$541,$F27))
B28: =IF($F28="","",INDEX(배정!$B$2:$B$541,$F28)&" ("&INDEX(배정!$C$2:$C$541,$F28)&")") | C28: =IF($F28="","",INDEX(배정!$D$2:$D$541,$F28)) | D28: =IF($F28="","",INDEX(배정!$E$2:$E$541,$F28)) | E28: 김재헌 | F28: =IF(ISNA(MATCH($E28&"|"&5,배정!$G$2:$G$541,0)),"",MATCH($E28&"|"&5,배정!$G$2:$G$541,0)) | G28: =IF($F28="","",INDEX(배정!$C$2:$C$541,$F28))
B29: =IF($F29="","",INDEX(배정!$B$2:$B$541,$F29)&" ("&INDEX(배정!$C$2:$C$541,$F29)&")") | C29: =IF($F29="","",INDEX(배정!$D$2:$D$541,$F29)) | D29: =IF($F29="","",INDEX(배정!$E$2:$E$541,$F29)) | E29: 김재헌 | F29: =IF(ISNA(MATCH($E29&"|"&6,배정!$G$2:$G$541,0)),"",MATCH($E29&"|"&6,배정!$G$2:$G$541,0)) | G29: =IF($F29="","",INDEX(배정!$C$2:$C$541,$F29))
B30: =IF($F30="","",INDEX(배정!$B$2:$B$541,$F30)&" ("&INDEX(배정!$C$2:$C$541,$F30)&")") | C30: =IF($F30="","",INDEX(배정!$D$2:$D$541,$F30)) | D30: =IF($F30="","",INDEX(배정!$E$2:$E$541,$F30)) | E30: 김재헌 | F30: =IF(ISNA(MATCH($E30&"|"&7,배정!$G$2:$G$541,0)),"",MATCH($E30&"|"&7,배정!$G$2:$G$541,0)) | G30: =IF($F30="","",INDEX(배정!$C$2:$C$541,$F30))
B31: =IF($F31="","",INDEX(배정!$B$2:$B$541,$F31)&" ("&INDEX(배정!$C$2:$C$541,$F31)&")") | C31: =IF($F31="","",INDEX(배정!$D$2:$D$541,$F31)) | D31: =IF($F31="","",INDEX(배정!$E$2:$E$541,$F31)) | E31: 김재헌 | F31: =IF(ISNA(MATCH($E31&"|"&8,배정!$G$2:$G$541,0)),"",MATCH($E31&"|"&8,배정!$G$2:$G$541,0)) | G31: =IF($F31="","",INDEX(배정!$C$2:$C$541,$F31))
B32: =IF($F32="","",INDEX(배정!$B$2:$B$541,$F32)&" ("&INDEX(배정!$C$2:$C$541,$F32)&")") | C32: =IF($F32="","",INDEX(배정!$D$2:$D$541,$F32)) | D32: =IF($F32="","",INDEX(배정!$E$2:$E$541,$F32)) | E32: 김재헌 | F32: =IF(ISNA(MATCH($E32&"|"&9,배정!$G$2:$G$541,0)),"",MATCH($E32&"|"&9,배정!$G$2:$G$541,0)) | G32: =IF($F32="","",INDEX(배정!$C$2:$C$541,$F32))
B33: =IF($F33="","",INDEX(배정!$B$2:$B$541,$F33)&" ("&INDEX(배정!$C$2:$C$541,$F33)&")") | C33: =IF($F33="","",INDEX(배정!$D$2:$D$541,$F33)) | D33: =IF($F33="","",INDEX(배정!$E$2:$E$541,$F33)) | E33: 김재헌 | F33: =IF(ISNA(MATCH($E33&"|"&10,배정!$G$2:$G$541,0)),"",MATCH($E33&"|"&10,배정!$G$2:$G$541,0)) | G33: =IF($F33="","",INDEX(배정!$C$2:$C$541,$F33))
A34: 양한규 수석 | B34: =IF($F34="","",INDEX(배정!$B$2:$B$541,$F34)&" ("&INDEX(배정!$C$2:$C$541,$F34)&")") | C34: =IF($F34="","",INDEX(배정!$D$2:$D$541,$F34)) | D34: =IF($F34="","",INDEX(배정!$E$2:$E$541,$F34)) | E34: 양한규 | F34: =IF(ISNA(MATCH($E34&"|"&1,배정!$G$2:$G$541,0)),"",MATCH($E34&"|"&1,배정!$G$2:$G$541,0)) | G34: =IF($F34="","",INDEX(배정!$C$2:$C$541,$F34))
B35: =IF($F35="","",INDEX(배정!$B$2:$B$541,$F35)&" ("&INDEX(배정!$C$2:$C$541,$F35)&")") | C35: =IF($F35="","",INDEX(배정!$D$2:$D$541,$F35)) | D35: =IF($F35="","",INDEX(배정!$E$2:$E$541,$F35)) | E35: 양한규 | F35: =IF(ISNA(MATCH($E35&"|"&2,배정!$G$2:$G$541,0)),"",MATCH($E35&"|"&2,배정!$G$2:$G$541,0)) | G35: =IF($F35="","",INDEX(배정!$C$2:$C$541,$F35))
B36: =IF($F36="","",INDEX(배정!$B$2:$B$541,$F36)&" ("&INDEX(배정!$C$2:$C$541,$F36)&")") | C36: =IF($F36="","",INDEX(배정!$D$2:$D$541,$F36)) | D36: =IF($F36="","",INDEX(배정!$E$2:$E$541,$F36)) | E36: 양한규 | F36: =IF(ISNA(MATCH($E36&"|"&3,배정!$G$2:$G$541,0)),"",MATCH($E36&"|"&3,배정!$G$2:$G$541,0)) | G36: =IF($F36="","",INDEX(배정!$C$2:$C$541,$F36))
B37: =IF($F37="","",INDEX(배정!$B$2:$B$541,$F37)&" ("&INDEX(배정!$C$2:$C$541,$F37)&")") | C37: =IF($F37="","",INDEX(배정!$D$2:$D$541,$F37)) | D37: =IF($F37="","",INDEX(배정!$E$2:$E$541,$F37)) | E37: 양한규 | F37: =IF(ISNA(MATCH($E37&"|"&4,배정!$G$2:$G$541,0)),"",MATCH($E37&"|"&4,배정!$G$2:$G$541,0)) | G37: =IF($F37="","",INDEX(배정!$C$2:$C$541,$F37))
B38: =IF($F38="","",INDEX(배정!$B$2:$B$541,$F38)&" ("&INDEX(배정!$C$2:$C$541,$F38)&")") | C38: =IF($F38="","",INDEX(배정!$D$2:$D$541,$F38)) | D38: =IF($F38="","",INDEX(배정!$E$2:$E$541,$F38)) | E38: 양한규 | F38: =IF(ISNA(MATCH($E38&"|"&5,배정!$G$2:$G$541,0)),"",MATCH($E38&"|"&5,배정!$G$2:$G$541,0)) | G38: =IF($F38="","",INDEX(배정!$C$2:$C$541,$F38))
B39: =IF($F39="","",INDEX(배정!$B$2:$B$541,$F39)&" ("&INDEX(배정!$C$2:$C$541,$F39)&")") | C39: =IF($F39="","",INDEX(배정!$D$2:$D$541,$F39)) | D39: =IF($F39="","",INDEX(배정!$E$2:$E$541,$F39)) | E39: 양한규 | F39: =IF(ISNA(MATCH($E39&"|"&6,배정!$G$2:$G$541,0)),"",MATCH($E39&"|"&6,배정!$G$2:$G$541,0)) | G39: =IF($F39="","",INDEX(배정!$C$2:$C$541,$F39))
B40: =IF($F40="","",INDEX(배정!$B$2:$B$541,$F40)&" ("&INDEX(배정!$C$2:$C$541,$F40)&")") | C40: =IF($F40="","",INDEX(배정!$D$2:$D$541,$F40)) | D40: =IF($F40="","",INDEX(배정!$E$2:$E$541,$F40)) | E40: 양한규 | F40: =IF(ISNA(MATCH($E40&"|"&7,배정!$G$2:$G$541,0)),"",MATCH($E40&"|"&7,배정!$G$2:$G$541,0)) | G40: =IF($F40="","",INDEX(배정!$C$2:$C$541,$F40))
...

Sheet 설정
A1: 공종별 표준 투입일수(근무일). PM=0=전기간. 숫자만 바꾸면 달력 막대 길이 자동
A3: 공종 | B3: 표준일수
A4: PM | B4: 0
A5: 검토 | B5: 3
A6: 내역 | B6: 3
A7: 가설 | B7: 3
A8: 세대 | B8: 5
A9: 내부 | B9: 7
A10: 외부 | B10: 5
A11: 창호 | B11: 4
A12: 조적 | B12: 4

Sheet 작성 가이드
B1: 사용법
B3: 입력 | C3: [진행중] 시트에만 입력. 마감/구조/토목 + PM~조적 칸에 담당자 선택, 작업시작일·납품일 입력
B4: 자동연동 | C4: 입력 즉시 [업무 달력]에 직원별로 막대 자동 생성. 새로고침 불필요
B5: 공종 일수 | C5: [설정] 시트 숫자로 공종별 투입일수 조정(PM=0=전기간)
B6: 줄 분리 | C6: 한 직원이 동시에 여러 공종이면 여러 줄에 표시(직원당 최대 10개)
B7: 완료 제외 | C7: 현재상태=완료면 달력에서 자동 제외
B8: 주의 | C8: 날짜는 반드시 날짜형식(2026-03-06). 배정 시트(숨김)는 계산용이니 건드리지 마세요

Sheet 배정
A1: 담당 | B1: 업무명 | C1: 공종 | D1: 시작 | E1: 종료 | F1: 순번 | G1: 키
A2: =IF(AND(진행중!D5<>"",진행중!V5<>"",진행중!L5<>"",진행중!L5<>"X",진행중!AA5<>"완료"),진행중!L5,"") | B2: =IF($A2="","",진행중!D5) | C2: PM | D2: =IF($A2="","",진행중!V5) | E2: =IF($A2="","",IF(VLOOKUP($C2,설정!$A$4:$B$12,2,0)=0,진행중!W5,MIN(WORKDAY(진행중!V5,VLOOKUP($C2,설정!$A$4:$B$12,2,0)-1),진행중!W5))) | F2: =IF($A2="","",COUNTIF($A$2:$A2,$A2)) | G2: =IF($A2="","",$A2&"|"&$F2)
A3: =IF(AND(진행중!D5<>"",진행중!V5<>"",진행중!M5<>"",진행중!M5<>"X",진행중!AA5<>"완료"),진행중!M5,"") | B3: =IF($A3="","",진행중!D5) | C3: 검토 | D3: =IF($A3="","",진행중!V5) | E3: =IF($A3="","",IF(VLOOKUP($C3,설정!$A$4:$B$12,2,0)=0,진행중!W5,MIN(WORKDAY(진행중!V5,VLOOKUP($C3,설정!$A$4:$B$12,2,0)-1),진행중!W5))) | F3: =IF($A3="","",COUNTIF($A$2:$A3,$A3)) | G3: =IF($A3="","",$A3&"|"&$F3)
A4: =IF(AND(진행중!D5<>"",진행중!V5<>"",진행중!N5<>"",진행중!N5<>"X",진행중!AA5<>"완료"),진행중!N5,"") | B4: =IF($A4="","",진행중!D5) | C4: 내역 | D4: =IF($A4="","",진행중!V5) | E4: =IF($A4="","",IF(VLOOKUP($C4,설정!$A$4:$B$12,2,0)=0,진행중!W5,MIN(WORKDAY(진행중!V5,VLOOKUP($C4,설정!$A$4:$B$12,2,0)-1),진행중!W5))) | F4: =IF($A4="","",COUNTIF($A$2:$A4,$A4)) | G4: =IF($A4="","",$A4&"|"&$F4)
A5: =IF(AND(진행중!D5<>"",진행중!V5<>"",진행중!O5<>"",진행중!O5<>"X",진행중!AA5<>"완료"),진행중!O5,"") | B5: =IF($A5="","",진행중!D5) | C5: 가설 | D5: =IF($A5="","",진행중!V5) | E5: =IF($A5="","",IF(VLOOKUP($C5,설정!$A$4:$B$12,2,0)=0,진행중!W5,MIN(WORKDAY(진행중!V5,VLOOKUP($C5,설정!$A$4:$B$12,2,0)-1),진행중!W5))) | F5: =IF($A5="","",COUNTIF($A$2:$A5,$A5)) | G5: =IF($A5="","",$A5&"|"&$F5)
A6: =IF(AND(진행중!D5<>"",진행중!V5<>"",진행중!P5<>"",진행중!P5<>"X",진행중!AA5<>"완료"),진행중!P5,"") | B6: =IF($A6="","",진행중!D5) | C6: 세대 | D6: =IF($A6="","",진행중!V5) | E6: =IF($A6="","",IF(VLOOKUP($C6,설정!$A$4:$B$12,2,0)=0,진행중!W5,MIN(WORKDAY(진행중!V5,VLOOKUP($C6,설정!$A$4:$B$12,2,0)-1),진행중!W5))) | F6: =IF($A6="","",COUNTIF($A$2:$A6,$A6)) | G6: =IF($A6="","",$A6&"|"&$F6)
A7: =IF(AND(진행중!D5<>"",진행중!V5<>"",진행중!Q5<>"",진행중!Q5<>"X",진행중!AA5<>"완료"),진행중!Q5,"") | B7: =IF($A7="","",진행중!D5) | C7: 내부 | D7: =IF($A7="","",진행중!V5) | E7: =IF($A7="","",IF(VLOOKUP($C7,설정!$A$4:$B$12,2,0)=0,진행중!W5,MIN(WORKDAY(진행중!V5,VLOOKUP($C7,설정!$A$4:$B$12,2,0)-1),진행중!W5))) | F7: =IF($A7="","",COUNTIF($A$2:$A7,$A7)) | G7: =IF($A7="","",$A7&"|"&$F7)
A8: =IF(AND(진행중!D5<>"",진행중!V5<>"",진행중!R5<>"",진행중!R5<>"X",진행중!AA5<>"완료"),진행중!R5,"") | B8: =IF($A8="","",진행중!D5) | C8: 외부 | D8: =IF($A8="","",진행중!V5) | E8: =IF($A8="","",IF(VLOOKUP($C8,설정!$A$4:$B$12,2,0)=0,진행중!W5,MIN(WORKDAY(진행중!V5,VLOOKUP($C8,설정!$A$4:$B$12,2,0)-1),진행중!W5))) | F8: =IF($A8="","",COUNTIF($A$2:$A8,$A8)) | G8: =IF($A8="","",$A8&"|"&$F8)
A9: =IF(AND(진행중!D5<>"",진행중!V5<>"",진행중!S5<>"",진행중!S5<>"X",진행중!AA5<>"완료"),진행중!S5,"") | B9: =IF($A9="","",진행중!D5) | C9: 창호 | D9: =IF($A9="","",진행중!V5) | E9: =IF($A9="","",IF(VLOOKUP($C9,설정!$A$4:$B$12,2,0)=0,진행중!W5,MIN(WORKDAY(진행중!V5,VLOOKUP($C9,설정!$A$4:$B$12,2,0)-1),진행중!W5))) | F9: =IF($A9="","",COUNTIF($A$2:$A9,$A9)) | G9: =IF($A9="","",$A9&"|"&$F9)
A10: =IF(AND(진행중!D5<>"",진행중!V5<>"",진행중!T5<>"",진행중!T5<>"X",진행중!AA5<>"완료"),진행중!T5,"") | B10: =IF($A10="","",진행중!D5) | C10: 조적 | D10: =IF($A10="","",진행중!V5) | E10: =IF($A10="","",IF(VLOOKUP($C10,설정!$A$4:$B$12,2,0)=0,진행중!W5,MIN(WORKDAY(진행중!V5,VLOOKUP($C10,설정!$A$4:$B$12,2,0)-1),진행중!W5))) | F10: =IF($A10="","",COUNTIF($A$2:$A10,$A10)) | G10: =IF($A10="","",$A10&"|"&$F10)
A11: =IF(AND(진행중!D6<>"",진행중!V6<>"",진행중!L6<>"",진행중!L6<>"X",진행중!AA6<>"완료"),진행중!L6,"") | B11: =IF($A11="","",진행중!D6) | C11: PM | D11: =IF($A11="","",진행중!V6) | E11: =IF($A11="","",IF(VLOOKUP($C11,설정!$A$4:$B$12,2,0)=0,진행중!W6,MIN(WORKDAY(진행중!V6,VLOOKUP($C11,설정!$A$4:$B$12,2,0)-1),진행중!W6))) | F11: =IF($A11="","",COUNTIF($A$2:$A11,$A11)) | G11: =IF($A11="","",$A11&"|"&$F11)
A12: =IF(AND(진행중!D6<>"",진행중!V6<>"",진행중!M6<>"",진행중!M6<>"X",진행중!AA6<>"완료"),진행중!M6,"") | B12: =IF($A12="","",진행중!D6) | C12: 검토 | D12: =IF($A12="","",진행중!V6) | E12: =IF($A12="","",IF(VLOOKUP($C12,설정!$A$4:$B$12,2,0)=0,진행중!W6,MIN(WORKDAY(진행중!V6,VLOOKUP($C12,설정!$A$4:$B$12,2,0)-1),진행중!W6))) | F12: =IF($A12="","",COUNTIF($A$2:$A12,$A12)) | G12: =IF($A12="","",$A12&"|"&$F12)
A13: =IF(AND(진행중!D6<>"",진행중!V6<>"",진행중!N6<>"",진행중!N6<>"X",진행중!AA6<>"완료"),진행중!N6,"") | B13: =IF($A13="","",진행중!D6) | C13: 내역 | D13: =IF($A13="","",진행중!V6) | E13: =IF($A13="","",IF(VLOOKUP($C13,설정!$A$4:$B$12,2,0)=0,진행중!W6,MIN(WORKDAY(진행중!V6,VLOOKUP($C13,설정!$A$4:$B$12,2,0)-1),진행중!W6))) | F13: =IF($A13="","",COUNTIF($A$2:$A13,$A13)) | G13: =IF($A13="","",$A13&"|"&$F13)
A14: =IF(AND(진행중!D6<>"",진행중!V6<>"",진행중!O6<>"",진행중!O6<>"X",진행중!AA6<>"완료"),진행중!O6,"") | B14: =IF($A14="","",진행중!D6) | C14: 가설 | D14: =IF($A14="","",진행중!V6) | E14: =IF($A14="","",IF(VLOOKUP($C14,설정!$A$4:$B$12,2,0)=0,진행중!W6,MIN(WORKDAY(진행중!V6,VLOOKUP($C14,설정!$A$4:$B$12,2,0)-1),진행중!W6))) | F14: =IF($A14="","",COUNTIF($A$2:$A14,$A14)) | G14: =IF($A14="","",$A14&"|"&$F14)
A15: =IF(AND(진행중!D6<>"",진행중!V6<>"",진행중!P6<>"",진행중!P6<>"X",진행중!AA6<>"완료"),진행중!P6,"") | B15: =IF($A15="","",진행중!D6) | C15: 세대 | D15: =IF($A15="","",진행중!V6) | E15: =IF($A15="","",IF(VLOOKUP($C15,설정!$A$4:$B$12,2,0)=0,진행중!W6,MIN(WORKDAY(진행중!V6,VLOOKUP($C15,설정!$A$4:$B$12,2,0)-1),진행중!W6))) | F15: =IF($A15="","",COUNTIF($A$2:$A15,$A15)) | G15: =IF($A15="","",$A15&"|"&$F15)
A16: =IF(AND(진행중!D6<>"",진행중!V6<>"",진행중!Q6<>"",진행중!Q6<>"X",진행중!AA6<>"완료"),진행중!Q6,"") | B16: =IF($A16="","",진행중!D6) | C16: 내부 | D16: =IF($A16="","",진행중!V6) | E16: =IF($A16="","",IF(VLOOKUP($C16,설정!$A$4:$B$12,2,0)=0,진행중!W6,MIN(WORKDAY(진행중!V6,VLOOKUP($C16,설정!$A$4:$B$12,2,0)-1),진행중!W6))) | F16: =IF($A16="","",COUNTIF($A$2:$A16,$A16)) | G16: =IF($A16="","",$A16&"|"&$F16)
A17: =IF(AND(진행중!D6<>"",진행중!V6<>"",진행중!R6<>"",진행중!R6<>"X",진행중!AA6<>"완료"),진행중!R6,"") | B17: =IF($A17="","",진행중!D6) | C17: 외부 | D17: =IF($A17="","",진행중!V6) | E17: =IF($A17="","",IF(VLOOKUP($C17,설정!$A$4:$B$12,2,0)=0,진행중!W6,MIN(WORKDAY(진행중!V6,VLOOKUP($C17,설정!$A$4:$B$12,2,0)-1),진행중!W6))) | F17: =IF($A17="","",COUNTIF($A$2:$A17,$A17)) | G17: =IF($A17="","",$A17&"|"&$F17)
A18: =IF(AND(진행중!D6<>"",진행중!V6<>"",진행중!S6<>"",진행중!S6<>"X",진행중!AA6<>"완료"),진행중!S6,"") | B18: =IF($A18="","",진행중!D6) | C18: 창호 | D18: =IF($A18="","",진행중!V6) | E18: =IF($A18="","",IF(VLOOKUP($C18,설정!$A$4:$B$12,2,0)=0,진행중!W6,MIN(WORKDAY(진행중!V6,VLOOKUP($C18,설정!$A$4:$B$12,2,0)-1),진행중!W6))) | F18: =IF($A18="","",COUNTIF($A$2:$A18,$A18)) | G18: =IF($A18="","",$A18&"|"&$F18)
A19: =IF(AND(진행중!D6<>"",진행중!V6<>"",진행중!T6<>"",진행중!T6<>"X",진행중!AA6<>"완료"),진행중!T6,"") | B19: =IF($A19="","",진행중!D6) | C19: 조적 | D19: =IF($A19="","",진행중!V6) | E19: =IF($A19="","",IF(VLOOKUP($C19,설정!$A$4:$B$12,2,0)=0,진행중!W6,MIN(WORKDAY(진행중!V6,VLOOKUP($C19,설정!$A$4:$B$12,2,0)-1),진행중!W6))) | F19: =IF($A19="","",COUNTIF($A$2:$A19,$A19)) | G19: =IF($A19="","",$A19&"|"&$F19)
A20: =IF(AND(진행중!D7<>"",진행중!V7<>"",진행중!L7<>"",진행중!L7<>"X",진행중!AA7<>"완료"),진행중!L7,"") | B20: =IF($A20="","",진행중!D7) | C20: PM | D20: =IF($A20="","",진행중!V7) | E20: =IF($A20="","",IF(VLOOKUP($C20,설정!$A$4:$B$12,2,0)=0,진행중!W7,MIN(WORKDAY(진행중!V7,VLOOKUP($C20,설정!$A$4:$B$12,2,0)-1),진행중!W7))) | F20: =IF($A20="","",COUNTIF($A$2:$A20,$A20)) | G20: =IF($A20="","",$A20&"|"&$F20)
A21: =IF(AND(진행중!D7<>"",진행중!V7<>"",진행중!M7<>"",진행중!M7<>"X",진행중!AA7<>"완료"),진행중!M7,"") | B21: =IF($A21="","",진행중!D7) | C21: 검토 | D21: =IF($A21="","",진행중!V7) | E21: =IF($A21="","",IF(VLOOKUP($C21,설정!$A$4:$B$12,2,0)=0,진행중!W7,MIN(WORKDAY(진행중!V7,VLOOKUP($C21,설정!$A$4:$B$12,2,0)-1),진행중!W7))) | F21: =IF($A21="","",COUNTIF($A$2:$A21,$A21)) | G21: =IF($A21="","",$A21&"|"&$F21)
A22: =IF(AND(진행중!D7<>"",진행중!V7<>"",진행중!N7<>"",진행중!N7<>"X",진행중!AA7<>"완료"),진행중!N7,"") | B22: =IF($A22="","",진행중!D7) | C22: 내역 | D22: =IF($A22="","",진행중!V7) | E22: =IF($A22="","",IF(VLOOKUP($C22,설정!$A$4:$B$12,2,0)=0,진행중!W7,MIN(WORKDAY(진행중!V7,VLOOKUP($C22,설정!$A$4:$B$12,2,0)-1),진행중!W7))) | F22: =IF($A22="","",COUNTIF($A$2:$A22,$A22)) | G22: =IF($A22="","",$A22&"|"&$F22)
A23: =IF(AND(진행중!D7<>"",진행중!V7<>"",진행중!O7<>"",진행중!O7<>"X",진행중!AA7<>"완료"),진행중!O7,"") | B23: =IF($A23="","",진행중!D7) | C23: 가설 | D23: =IF($A23="","",진행중!V7) | E23: =IF($A23="","",IF(VLOOKUP($C23,설정!$A$4:$B$12,2,0)=0,진행중!W7,MIN(WORKDAY(진행중!V7,VLOOKUP($C23,설정!$A$4:$B$12,2,0)-1),진행중!W7))) | F23: =IF($A23="","",COUNTIF($A$2:$A23,$A23)) | G23: =IF($A23="","",$A23&"|"&$F23)
A24: =IF(AND(진행중!D7<>"",진행중!V7<>"",진행중!P7<>"",진행중!P7<>"X",진행중!AA7<>"완료"),진행중!P7,"") | B24: =IF($A24="","",진행중!D7) | C24: 세대 | D24: =IF($A24="","",진행중!V7) | E24: =IF($A24="","",IF(VLOOKUP($C24,설정!$A$4:$B$12,2,0)=0,진행중!W7,MIN(WORKDAY(진행중!V7,VLOOKUP($C24,설정!$A$4:$B$12,2,0)-1),진행중!W7))) | F24: =IF($A24="","",COUNTIF($A$2:$A24,$A24)) | G24: =IF($A24="","",$A24&"|"&$F24)
A25: =IF(AND(진행중!D7<>"",진행중!V7<>"",진행중!Q7<>"",진행중!Q7<>"X",진행중!AA7<>"완료"),진행중!Q7,"") | B25: =IF($A25="","",진행중!D7) | C25: 내부 | D25: =IF($A25="","",진행중!V7) | E25: =IF($A25="","",IF(VLOOKUP($C25,설정!$A$4:$B$12,2,0)=0,진행중!W7,MIN(WORKDAY(진행중!V7,VLOOKUP($C25,설정!$A$4:$B$12,2,0)-1),진행중!W7))) | F25: =IF($A25="","",COUNTIF($A$2:$A25,$A25)) | G25: =IF($A25="","",$A25&"|"&$F25)
A26: =IF(AND(진행중!D7<>"",진행중!V7<>"",진행중!R7<>"",진행중!R7<>"X",진행중!AA7<>"완료"),진행중!R7,"") | B26: =IF($A26="","",진행중!D7) | C26: 외부 | D26: =IF($A26="","",진행중!V7) | E26: =IF($A26="","",IF(VLOOKUP($C26,설정!$A$4:$B$12,2,0)=0,진행중!W7,MIN(WORKDAY(진행중!V7,VLOOKUP($C26,설정!$A$4:$B$12,2,0)-1),진행중!W7))) | F26: =IF($A26="","",COUNTIF($A$2:$A26,$A26)) | G26: =IF($A26="","",$A26&"|"&$F26)
A27: =IF(AND(진행중!D7<>"",진행중!V7<>"",진행중!S7<>"",진행중!S7<>"X",진행중!AA7<>"완료"),진행중!S7,"") | B27: =IF($A27="","",진행중!D7) | C27: 창호 | D27: =IF($A27="","",진행중!V7) | E27: =IF($A27="","",IF(VLOOKUP($C27,설정!$A$4:$B$12,2,0)=0,진행중!W7,MIN(WORKDAY(진행중!V7,VLOOKUP($C27,설정!$A$4:$B$12,2,0)-1),진행중!W7))) | F27: =IF($A27="","",COUNTIF($A$2:$A27,$A27)) | G27: =IF($A27="","",$A27&"|"&$F27)
A28: =IF(AND(진행중!D7<>"",진행중!V7<>"",진행중!T7<>"",진행중!T7<>"X",진행중!AA7<>"완료"),진행중!T7,"") | B28: =IF($A28="","",진행중!D7) | C28: 조적 | D28: =IF($A28="","",진행중!V7) | E28: =IF($A28="","",IF(VLOOKUP($C28,설정!$A$4:$B$12,2,0)=0,진행중!W7,MIN(WORKDAY(진행중!V7,VLOOKUP($C28,설정!$A$4:$B$12,2,0)-1),진행중!W7))) | F28: =IF($A28="","",COUNTIF($A$2:$A28,$A28)) | G28: =IF($A28="","",$A28&"|"&$F28)
A29: =IF(AND(진행중!D8<>"",진행중!V8<>"",진행중!L8<>"",진행중!L8<>"X",진행중!AA8<>"완료"),진행중!L8,"") | B29: =IF($A29="","",진행중!D8) | C29: PM | D29: =IF($A29="","",진행중!V8) | E29: =IF($A29="","",IF(VLOOKUP($C29,설정!$A$4:$B$12,2,0)=0,진행중!W8,MIN(WORKDAY(진행중!V8,VLOOKUP($C29,설정!$A$4:$B$12,2,0)-1),진행중!W8))) | F29: =IF($A29="","",COUNTIF($A$2:$A29,$A29)) | G29: =IF($A29="","",$A29&"|"&$F29)
A30: =IF(AND(진행중!D8<>"",진행중!V8<>"",진행중!M8<>"",진행중!M8<>"X",진행중!AA8<>"완료"),진행중!M8,"") | B30: =IF($A30="","",진행중!D8) | C30: 검토 | D30: =IF($A30="","",진행중!V8) | E30: =IF($A30="","",IF(VLOOKUP($C30,설정!$A$4:$B$12,2,0)=0,진행중!W8,MIN(WORKDAY(진행중!V8,VLOOKUP($C30,설정!$A$4:$B$12,2,0)-1),진행중!W8))) | F30: =IF($A30="","",COUNTIF($A$2:$A30,$A30)) | G30: =IF($A30="","",$A30&"|"&$F30)
A31: =IF(AND(진행중!D8<>"",진행중!V8<>"",진행중!N8<>"",진행중!N8<>"X",진행중!AA8<>"완료"),진행중!N8,"") | B31: =IF($A31="","",진행중!D8) | C31: 내역 | D31: =IF($A31="","",진행중!V8) | E31: =IF($A31="","",IF(VLOOKUP($C31,설정!$A$4:$B$12,2,0)=0,진행중!W8,MIN(WORKDAY(진행중!V8,VLOOKUP($C31,설정!$A$4:$B$12,2,0)-1),진행중!W8))) | F31: =IF($A31="","",COUNTIF($A$2:$A31,$A31)) | G31: =IF($A31="","",$A31&"|"&$F31)
A32: =IF(AND(진행중!D8<>"",진행중!V8<>"",진행중!O8<>"",진행중!O8<>"X",진행중!AA8<>"완료"),진행중!O8,"") | B32: =IF($A32="","",진행중!D8) | C32: 가설 | D32: =IF($A32="","",진행중!V8) | E32: =IF($A32="","",IF(VLOOKUP($C32,설정!$A$4:$B$12,2,0)=0,진행중!W8,MIN(WORKDAY(진행중!V8,VLOOKUP($C32,설정!$A$4:$B$12,2,0)-1),진행중!W8))) | F32: =IF($A32="","",COUNTIF($A$2:$A32,$A32)) | G32: =IF($A32="","",$A32&"|"&$F32)
A33: =IF(AND(진행중!D8<>"",진행중!V8<>"",진행중!P8<>"",진행중!P8<>"X",진행중!AA8<>"완료"),진행중!P8,"") | B33: =IF($A33="","",진행중!D8) | C33: 세대 | D33: =IF($A33="","",진행중!V8) | E33: =IF($A33="","",IF(VLOOKUP($C33,설정!$A$4:$B$12,2,0)=0,진행중!W8,MIN(WORKDAY(진행중!V8,VLOOKUP($C33,설정!$A$4:$B$12,2,0)-1),진행중!W8))) | F33: =IF($A33="","",COUNTIF($A$2:$A33,$A33)) | G33: =IF($A33="","",$A33&"|"&$F33)
A34: =IF(AND(진행중!D8<>"",진행중!V8<>"",진행중!Q8<>"",진행중!Q8<>"X",진행중!AA8<>"완료"),진행중!Q8,"") | B34: =IF($A34="","",진행중!D8) | C34: 내부 | D34: =IF($A34="","",진행중!V8) | E34: =IF($A34="","",IF(VLOOKUP($C34,설정!$A$4:$B$12,2,0)=0,진행중!W8,MIN(WORKDAY(진행중!V8,VLOOKUP($C34,설정!$A$4:$B$12,2,0)-1),진행중!W8))) | F34: =IF($A34="","",COUNTIF($A$2:$A34,$A34)) | G34: =IF($A34="","",$A34&"|"&$F34)
A35: =IF(AND(진행중!D8<>"",진행중!V8<>"",진행중!R8<>"",진행중!R8<>"X",진행중!AA8<>"완료"),진행중!R8,"") | B35: =IF($A35="","",진행중!D8) | C35: 외부 | D35: =IF($A35="","",진행중!V8) | E35: =IF($A35="","",IF(VLOOKUP($C35,설정!$A$4:$B$12,2,0)=0,진행중!W8,MIN(WORKDAY(진행중!V8,VLOOKUP($C35,설정!$A$4:$B$12,2,0)-1),진행중!W8))) | F35: =IF($A35="","",COUNTIF($A$2:$A35,$A35)) | G35: =IF($A35="","",$A35&"|"&$F35)
A36: =IF(AND(진행중!D8<>"",진행중!V8<>"",진행중!S8<>"",진행중!S8<>"X",진행중!AA8<>"완료"),진행중!S8,"") | B36: =IF($A36="","",진행중!D8) | C36: 창호 | D36: =IF($A36="","",진행중!V8) | E36: =IF($A36="","",IF(VLOOKUP($C36,설정!$A$4:$B$12,2,0)=0,진행중!W8,MIN(WORKDAY(진행중!V8,VLOOKUP($C36,설정!$A$4:$B$12,2,0)-1),진행중!W8))) | F36: =IF($A36="","",COUNTIF($A$2:$A36,$A36)) | G36: =IF($A36="","",$A36&"|"&$F36)
A37: =IF(AND(진행중!D8<>"",진행중!V8<>"",진행중!T8<>"",진행중!T8<>"X",진행중!AA8<>"완료"),진행중!T8,"") | B37: =IF($A37="","",진행중!D8) | C37: 조적 | D37: =IF($A37="","",진행중!V8) | E37: =IF($A37="","",IF(VLOOKUP($C37,설정!$A$4:$B$12,2,0)=0,진행중!W8,MIN(WORKDAY(진행중!V8,VLOOKUP($C37,설정!$A$4:$B$12,2,0)-1),진행중!W8))) | F37: =IF($A37="","",COUNTIF($A$2:$A37,$A37)) | G37: =IF($A37="","",$A37&"|"&$F37)
A38: =IF(AND(진행중!D9<>"",진행중!V9<>"",진행중!L9<>"",진행중!L9<>"X",진행중!AA9<>"완료"),진행중!L9,"") | B38: =IF($A38="","",진행중!D9) | C38: PM | D38: =IF($A38="","",진행중!V9) | E38: =IF($A38="","",IF(VLOOKUP($C38,설정!$A$4:$B$12,2,0)=0,진행중!W9,MIN(WORKDAY(진행중!V9,VLOOKUP($C38,설정!$A$4:$B$12,2,0)-1),진행중!W9))) | F38: =IF($A38="","",COUNTIF($A$2:$A38,$A38)) | G38: =IF($A38="","",$A38&"|"&$F38)
A39: =IF(AND(진행중!D9<>"",진행중!V9<>"",진행중!M9<>"",진행중!M9<>"X",진행중!AA9<>"완료"),진행중!M9,"") | B39: =IF($A39="","",진행중!D9) | C39: 검토 | D39: =IF($A39="","",진행중!V9) | E39: =IF($A39="","",IF(VLOOKUP($C39,설정!$A$4:$B$12,2,0)=0,진행중!W9,MIN(WORKDAY(진행중!V9,VLOOKUP($C39,설정!$A$4:$B$12,2,0)-1),진행중!W9))) | F39: =IF($A39="","",COUNTIF($A$2:$A39,$A39)) | G39: =IF($A39="","",$A39&"|"&$F39)
A40: =IF(AND(진행중!D9<>"",진행중!V9<>"",진행중!N9<>"",진행중!N9<>"X",진행중!AA9<>"완료"),진행중!N9,"") | B40: =IF($A40="","",진행중!D9) | C40: 내역 | D40: =IF($A40="","",진행중!V9) | E40: =IF($A40="","",IF(VLOOKUP($C40,설정!$A$4:$B$12,2,0)=0,진행중!W9,MIN(WORKDAY(진행중!V9,VLOOKUP($C40,설정!$A$4:$B$12,2,0)-1),진행중!W9))) | F40: =IF($A40="","",COUNTIF($A$2:$A40,$A40)) | G40: =IF($A40="","",$A40&"|"&$F40)
...
